<?xml version="1.0" ?>
<!-- =================================================================================== -->
<!-- |    This document was autogenerated by xacro from /home/xtark/ABB_ws/src/abb_experimental/abb_irb120_support/urdf/irb120_3_58.xacro | -->
<!-- |    EDITING THIS FILE BY HAND IS NOT RECOMMENDED                                 | -->
<!-- =================================================================================== -->
<robot name="abb_irb120_3_58" xmlns:xacro="http://ros.org/wiki/xacro" uuid="B6FB1E80-8999-4122-83B4-B18379E8C99C">
  <!-- Conversion were obtained from http://www.e-paint.co.uk/Lab_values.asp
       unless otherwise stated. -->
  <!-- link list -->
  <link name="link_6" uuid="8375A1E6-1DF2-44DE-BE54-E427B6EF7B22">
    <inertial>
      <mass value="6.215" />
      <origin rpy="0 0 0" xyz="-0.04204 8.01E-05 0.07964" />
      <inertia ixx="0.0247272" ixy="-8.0784E-05" ixz="0.00130902" iyy="0.0491285" iyz="-8.0419E-06" izz="0.0472376" />
    </inertial>
    <visual>
      <origin rpy="0 0 0" xyz="0 0 0" />
      <geometry>
        <mesh filename="package://abb_irb120_support/meshes/irb120_3_58/visual/base_link.stl" />
      </geometry>
      <material name="">
        <color rgba="0.7372549 0.3490196 0.1607843 1" />
      </material>
    </visual>
    <collision>
      <origin rpy="0 0 0" xyz="0 0 0" />
      <geometry>
        <mesh filename="package://abb_irb120_support/meshes/irb120_3_58/collision/base_link.stl" />
      </geometry>
      <material name="">
        <color rgba="1 1 0 1" />
      </material>
    </collision>
  </link>
  <link name="base_link" uuid="965B578F-4A5D-47EE-8F0A-6F26089FD54C">
    <inertial>
      <mass value="6.215" />
      <origin rpy="0 0 0" xyz="-0.04204 8.01E-05 0.07964" />
      <inertia ixx="0.0247272" ixy="-8.0784E-05" ixz="0.00130902" iyy="0.0491285" iyz="-8.0419E-06" izz="0.0472376" />
    </inertial>
    <visual>
      <origin rpy="0 0 0" xyz="0 0 0" />
      <geometry>
        <mesh filename="package://abb_irb120_support/meshes/irb120_3_58/visual/base_link.stl" />
      </geometry>
      <material name="">
        <color rgba="0.7372549 0.3490196 0.1607843 1" />
      </material>
    </visual>
    <collision>
      <origin rpy="0 0 0" xyz="0 0 0" />
      <geometry>
        <mesh filename="package://abb_irb120_support/meshes/irb120_3_58/collision/base_link.stl" />
      </geometry>
      <material name="">
        <color rgba="1 1 0 1" />
      </material>
    </collision>
  </link>
  <link name="link_1" uuid="13197BE0-3FE1-4B7A-A71C-B58E0C5D7D72">
    <inertial>
      <mass value="6.215" />
      <origin rpy="0 0 0" xyz="-0.04204 8.01E-05 0.07964" />
      <inertia ixx="0.0247272" ixy="-8.0784E-05" ixz="0.00130902" iyy="0.0491285" iyz="-8.0419E-06" izz="0.0472376" />
    </inertial>
    <visual>
      <origin rpy="0 0 0" xyz="0 0 0" />
      <geometry>
        <mesh filename="package://abb_irb120_support/meshes/irb120_3_58/visual/base_link.stl" />
      </geometry>
      <material name="">
        <color rgba="0.7372549 0.3490196 0.1607843 1" />
      </material>
    </visual>
    <collision>
      <origin rpy="0 0 0" xyz="0 0 0" />
      <geometry>
        <mesh filename="package://abb_irb120_support/meshes/irb120_3_58/collision/base_link.stl" />
      </geometry>
      <material name="">
        <color rgba="1 1 0 1" />
      </material>
    </collision>
  </link>
  <link name="link_2" uuid="9CB097B2-4ADC-4AE5-8E4E-8830D03FFC3D">
    <inertial>
      <mass value="6.215" />
      <origin rpy="0 0 0" xyz="-0.04204 8.01E-05 0.07964" />
      <inertia ixx="0.0247272" ixy="-8.0784E-05" ixz="0.00130902" iyy="0.0491285" iyz="-8.0419E-06" izz="0.0472376" />
    </inertial>
    <visual>
      <origin rpy="0 0 0" xyz="0 0 0" />
      <geometry>
        <mesh filename="package://abb_irb120_support/meshes/irb120_3_58/visual/base_link.stl" />
      </geometry>
      <material name="">
        <color rgba="0.7372549 0.3490196 0.1607843 1" />
      </material>
    </visual>
    <collision>
      <origin rpy="0 0 0" xyz="0 0 0" />
      <geometry>
        <mesh filename="package://abb_irb120_support/meshes/irb120_3_58/collision/base_link.stl" />
      </geometry>
      <material name="">
        <color rgba="1 1 0 1" /> 
      </material>
    </collision>
  </link>
  <link name="link_3" uuid="C314846C-D248-4738-ACBE-64229A30D357">
    <inertial>
      <mass value="6.215" />
      <origin rpy="0 0 0" xyz="-0.04204 8.01E-05 0.07964" />
      <inertia ixx="0.0247272" ixy="-8.0784E-05" ixz="0.00130902" iyy="0.0491285" iyz="-8.0419E-06" izz="0.0472376" />
    </inertial>
    <visual>
      <origin rpy="0 0 0" xyz="0 0 0" />
      <geometry>
        <mesh filename="package://abb_irb120_support/meshes/irb120_3_58/visual/base_link.stl" />
      </geometry>
      <material name="">
        <color rgba="0.7372549 0.3490196 0.1607843 1" />
      </material>
    </visual>
    <collision>
      <origin rpy="0 0 0" xyz="0 0 0" />
      <geometry>
        <mesh filename="package://abb_irb120_support/meshes/irb120_3_58/collision/base_link.stl" />
      </geometry>
      <material name="">
        <color rgba="1 1 0 1" />
      </material>
    </collision>
  </link>
  <link name="link_4" uuid="A3BF8CA7-0E2E-48F7-A6C9-6AE3FD97F3EB">
    <inertial>
      <mass value="6.215" />
      <origin rpy="0 0 0" xyz="-0.04204 8.01E-05 0.07964" />
      <inertia ixx="0.0247272" ixy="-8.0784E-05" ixz="0.00130902" iyy="0.0491285" iyz="-8.0419E-06" izz="0.0472376" />
    </inertial>
    <visual>
      <origin rpy="0 0 0" xyz="0 0 0" />
      <geometry>
        <mesh filename="package://abb_irb120_support/meshes/irb120_3_58/visual/base_link.stl" />
      </geometry>
      <material name="">
        <color rgba="0.7372549 0.3490196 0.1607843 1" />
      </material>
    </visual>
    <collision>
      <origin rpy="0 0 0" xyz="0 0 0" />
      <geometry>
        <mesh filename="package://abb_irb120_support/meshes/irb120_3_58/collision/base_link.stl" />
      </geometry>
      <material name="">
        <color rgba="1 1 0 1" />
      </material>
    </collision>
  </link>
  <link name="link_5" uuid="9659EFC3-53DD-4082-A47E-A8134D715637">
    <inertial>
      <mass value="6.215" />
      <origin rpy="0 0 0" xyz="-0.04204 8.01E-05 0.07964" />
      <inertia ixx="0.0247272" ixy="-8.0784E-05" ixz="0.00130902" iyy="0.0491285" iyz="-8.0419E-06" izz="0.0472376" />
    </inertial>
    <visual>
      <origin rpy="0 0 0" xyz="0 0 0" />
      <geometry>
        <mesh filename="package://abb_irb120_support/meshes/irb120_3_58/visual/base_link.stl" />
      </geometry>
      <material name="">
        <color rgba="0.7372549 0.3490196 0.1607843 1" />
      </material>
    </visual>
    <collision>
      <origin rpy="0 0 0" xyz="0 0 0" />
      <geometry>
        <mesh filename="package://abb_irb120_support/meshes/irb120_3_58/collision/base_link.stl" />
      </geometry>
      <material name="">
        <color rgba="1 1 0 1" />
      </material>
    </collision>
  </link>
  <!-- end of link list -->
  <!-- joint list -->
  <joint name="joint_4" type="revolute" innerId="6deafac9-5834-45fe-a790-95e42fdf5776">
    <origin rpy="0 0 0" xyz="0 0 0.115" />
    <parent link="link_3" uuid="C314846C-D248-4738-ACBE-64229A30D357" />
    <child link="link_4" uuid="A3BF8CA7-0E2E-48F7-A6C9-6AE3FD97F3EB" />
    <limit effort="0" lower="-4.380776" upper="4.380776" velocity="1.570796" />
    <axis xyz="1 0 0" />
    <dynamics damping="0.0" friction="0.0" />
  </joint>
  <joint name="joint_1" type="revolute" innerId="0df9269b-43a7-4049-9473-f7a7dd084ba0">
    <origin rpy="0 0 0" xyz="0 0 0" />
    <parent link="base_link" uuid="965B578F-4A5D-47EE-8F0A-6F26089FD54C" />
    <child link="link_1" uuid="13197BE0-3FE1-4B7A-A71C-B58E0C5D7D72" />
    <limit effort="0" lower="-3.141593" upper="3.141593" velocity="1.570796" />
    <axis xyz="0 0 1" />
    <dynamics damping="0.0" friction="0.0" />
  </joint>
  <joint name="joint_2" type="revolute" innerId="7f0c4c16-8f18-4d94-97db-a7f5e1954e85">
    <origin rpy="0 0 0" xyz="0.15 0 0.445" />
    <parent link="link_1" uuid="13197BE0-3FE1-4B7A-A71C-B58E0C5D7D72" />
    <child link="link_2" uuid="9CB097B2-4ADC-4AE5-8E4E-8830D03FFC3D" />
    <limit effort="0" lower="-1.658063" upper="2.70526" velocity="1.570796" />
    <axis xyz="0 1 0" />
    <dynamics damping="0.0" friction="0.0" />
  </joint>
  <joint name="joint_3" type="revolute" innerId="b65f1ed1-9d2a-4611-8bed-96e993ff9af9">
    <origin rpy="0 0 0" xyz="0 0 0.9" />
    <parent link="link_2" uuid="9CB097B2-4ADC-4AE5-8E4E-8830D03FFC3D" />
    <child link="link_3" uuid="C314846C-D248-4738-ACBE-64229A30D357" />
    <limit effort="0" lower="-3.141593" upper="1.308997" velocity="1.570796" />
    <axis xyz="0 1 0" />
    <dynamics damping="0.0" friction="0.0" />
  </joint>
  <joint name="joint_5" type="revolute" innerId="147219fd-2404-4863-bd16-2e1ea5989543">
    <origin rpy="0 0 0" xyz="0.795 0 0" />
    <parent link="link_4" uuid="A3BF8CA7-0E2E-48F7-A6C9-6AE3FD97F3EB" />
    <child link="link_5" uuid="9659EFC3-53DD-4082-A47E-A8134D715637" />
    <limit effort="0" lower="-2.094395" upper="2.094395" velocity="1.570796" />
    <axis xyz="0 1 0" />
    <dynamics damping="0.0" friction="0.0" />
  </joint>
  <joint name="joint_6" type="revolute" innerId="580959da-6a33-4873-9688-053008c57b3e">
    <origin rpy="0 0 0" xyz="0.085 0 0" />
    <parent link="link_5" uuid="9659EFC3-53DD-4082-A47E-A8134D715637" />
    <child link="link_6" uuid="8375A1E6-1DF2-44DE-BE54-E427B6EF7B22" />
    <limit effort="0" lower="-4.782202" upper="4.782202" velocity="1.570796" />
    <axis xyz="1 0 0" />
    <dynamics damping="0.0" friction="0.0" />
  </joint>
  <!-- end of joint list -->
  <!-- ROS-Industrial 'base' frame: base_link to ABB World Coordinates transform -->
  <link name="base" uuidBase="7C55A034-1DAD-456F-AE45-D78C7627B858" />
  <joint name="base_link-base" type="fixed">
    <origin rpy="0 0 0" xyz="0 0 0" />
    <parent link="base" />
    <child link="base_link" />
  </joint>
  <!-- ROS-Industrial 'flange' frame: attachment point for EEF models -->
  <link name="flange" />
  <joint name="joint_6-flange" type="fixed">
    <origin rpy="0 1.5707963267949 0" xyz="0 0 0" />
    <parent link="link_6" />
    <child link="flange" />
  </joint>
  <!-- ROS-Industrial 'tool0' frame: all-zeros tool frame -->
  <link name="tool0" uuidTool="24C4240F-C744-4AA2-9A27-5540D49C5B88" />
  <joint name="link_6-tool0" type="fixed">
    <origin rpy="0 0.524 0" xyz="0 0 0.2" />
    <parent link="flange" />
    <child link="tool0" />
  </joint>
  <gazebo>
    <plugin name="gazebo_ros_control" filename="libgazebo_ros_control.so">
      <robotNamespace>/</robotNamespace>
    </plugin>
  </gazebo>
</robot>